error: 
    status - 500 
    message - TypeError: UserService.userRegistration is not a function
    at _callee$ (H:\NodeJS\fundooNotes\fundooNotes\src\controllers\/user.controller.js:12:37)
    at tryCatch (H:\NodeJS\fundooNotes\fundooNotes\node_modules\@babel\runtime\helpers\regeneratorRuntime.js:86:17)
    at Generator._invoke (H:\NodeJS\fundooNotes\fundooNotes\node_modules\@babel\runtime\helpers\regeneratorRuntime.js:66:24)
    at Generator.next (H:\NodeJS\fundooNotes\fundooNotes\node_modules\@babel\runtime\helpers\regeneratorRuntime.js:117:21)
    at asyncGeneratorStep (H:\NodeJS\fundooNotes\fundooNotes\node_modules\@babel\runtime\helpers\asyncToGenerator.js:3:24)
    at _next (H:\NodeJS\fundooNotes\fundooNotes\node_modules\@babel\runtime\helpers\asyncToGenerator.js:25:9)
    at H:\NodeJS\fundooNotes\fundooNotes\node_modules\@babel\runtime\helpers\asyncToGenerator.js:32:7
    at new Promise (<anonymous>)
    at H:\NodeJS\fundooNotes\fundooNotes\node_modules\@babel\runtime\helpers\asyncToGenerator.js:21:12
    at userRegistration (H:\NodeJS\fundooNotes\fundooNotes\src\controllers\/user.controller.js:10:31)
    at Layer.handle [as handle_request] (H:\NodeJS\fundooNotes\fundooNotes\node_modules\express\lib\router\layer.js:95:5)
    at next (H:\NodeJS\fundooNotes\fundooNotes\node_modules\express\lib\router\route.js:144:13)
    at newUserValidator (H:\NodeJS\fundooNotes\fundooNotes\src\validators\/user.validator.js:19:5)
    at Layer.handle [as handle_request] (H:\NodeJS\fundooNotes\fundooNotes\node_modules\express\lib\router\layer.js:95:5)
    at next (H:\NodeJS\fundooNotes\fundooNotes\node_modules\express\lib\router\route.js:144:13)
    at Route.dispatch (H:\NodeJS\fundooNotes\fundooNotes\node_modules\express\lib\router\route.js:114:3) 
    url - /api/v1/users/userRegistration 
    method - POST 
    IP - ::1
   {"timestamp":"2022-07-28T17:15:58.476Z"}
error: 
      status - 11000
      message - E11000 duplicate key error collection: Fundoo_Notes.users index: email_1 dup key: { email: " rohitshinde@gmail.com " } 
      url - /api/v1/users/userRegistration 
      method - POST 
      IP - ::1
     {"timestamp":"2022-07-28T18:00:20.482Z"}
error: 
    status - 500 
    message - RangeError: Invalid status code: 11000
    at new NodeError (node:internal/errors:371:5)
    at ServerResponse.writeHead (node:_http_server:274:11)
    at ServerResponse.writeHead (H:\NodeJS\fundooNotes\fundooNotes\node_modules\on-headers\index.js:44:26)
    at ServerResponse._implicitHeader (node:_http_server:265:8)
    at write_ (node:_http_outgoing:766:9)
    at ServerResponse.end (node:_http_outgoing:855:5)
    at ServerResponse.send (H:\NodeJS\fundooNotes\fundooNotes\node_modules\express\lib\response.js:232:10)
    at ServerResponse.json (H:\NodeJS\fundooNotes\fundooNotes\node_modules\express\lib\response.js:278:15)
    at appErrorHandler (H:\NodeJS\fundooNotes\fundooNotes\src\middlewares\/error.middleware.js:36:26)
    at Layer.handle_error (H:\NodeJS\fundooNotes\fundooNotes\node_modules\express\lib\router\layer.js:71:5)
    at trim_prefix (H:\NodeJS\fundooNotes\fundooNotes\node_modules\express\lib\router\index.js:326:13)
    at H:\NodeJS\fundooNotes\fundooNotes\node_modules\express\lib\router\index.js:286:9
    at Function.process_params (H:\NodeJS\fundooNotes\fundooNotes\node_modules\express\lib\router\index.js:346:12)
    at Immediate.next (H:\NodeJS\fundooNotes\fundooNotes\node_modules\express\lib\router\index.js:280:10)
    at Immediate._onImmediate (H:\NodeJS\fundooNotes\fundooNotes\node_modules\express\lib\router\index.js:646:15)
    at processImmediate (node:internal/timers:468:21) 
    url - /api/v1/users/userRegistration 
    method - POST 
    IP - ::1
   {"timestamp":"2022-07-28T18:00:20.522Z"}
error: 
    status - 500 
    message - Error: User already exist
    at _callee$ (H:\NodeJS\fundooNotes\fundooNotes\src\services\/user.service.js:9:9)
    at tryCatch (H:\NodeJS\fundooNotes\fundooNotes\node_modules\@babel\runtime\helpers\regeneratorRuntime.js:86:17)
    at Generator._invoke (H:\NodeJS\fundooNotes\fundooNotes\node_modules\@babel\runtime\helpers\regeneratorRuntime.js:66:24)
    at Generator.next (H:\NodeJS\fundooNotes\fundooNotes\node_modules\@babel\runtime\helpers\regeneratorRuntime.js:117:21)
    at asyncGeneratorStep (H:\NodeJS\fundooNotes\fundooNotes\node_modules\@babel\runtime\helpers\asyncToGenerator.js:3:24)
    at _next (H:\NodeJS\fundooNotes\fundooNotes\node_modules\@babel\runtime\helpers\asyncToGenerator.js:25:9)
    at processTicksAndRejections (node:internal/process/task_queues:96:5) 
    url - /api/v1/users/userRegistration 
    method - POST 
    IP - ::1
   {"timestamp":"2022-07-28T18:11:58.484Z"}
error: 
    status - 500 
    message - Error: User not exist
    at _callee2$ (H:\NodeJS\fundooNotes\fundooNotes\src\services\/user.service.js:25:11)
    at tryCatch (H:\NodeJS\fundooNotes\fundooNotes\node_modules\@babel\runtime\helpers\regeneratorRuntime.js:86:17)
    at Generator._invoke (H:\NodeJS\fundooNotes\fundooNotes\node_modules\@babel\runtime\helpers\regeneratorRuntime.js:66:24)
    at Generator.next (H:\NodeJS\fundooNotes\fundooNotes\node_modules\@babel\runtime\helpers\regeneratorRuntime.js:117:21)
    at asyncGeneratorStep (H:\NodeJS\fundooNotes\fundooNotes\node_modules\@babel\runtime\helpers\asyncToGenerator.js:3:24)
    at _next (H:\NodeJS\fundooNotes\fundooNotes\node_modules\@babel\runtime\helpers\asyncToGenerator.js:25:9)
    at processTicksAndRejections (node:internal/process/task_queues:96:5) 
    url - /api/v1/users/login 
    method - POST 
    IP - ::1
   {"timestamp":"2022-07-28T18:22:47.733Z"}
error: 
    status - 500 
    message - Error: password not match
    at _callee2$ (H:\NodeJS\fundooNotes\fundooNotes\src\services\/user.service.js:33:11)
    at tryCatch (H:\NodeJS\fundooNotes\fundooNotes\node_modules\@babel\runtime\helpers\regeneratorRuntime.js:86:17)
    at Generator._invoke (H:\NodeJS\fundooNotes\fundooNotes\node_modules\@babel\runtime\helpers\regeneratorRuntime.js:66:24)
    at Generator.next (H:\NodeJS\fundooNotes\fundooNotes\node_modules\@babel\runtime\helpers\regeneratorRuntime.js:117:21)
    at asyncGeneratorStep (H:\NodeJS\fundooNotes\fundooNotes\node_modules\@babel\runtime\helpers\asyncToGenerator.js:3:24)
    at _next (H:\NodeJS\fundooNotes\fundooNotes\node_modules\@babel\runtime\helpers\asyncToGenerator.js:25:9) 
    url - /api/v1/users/login 
    method - POST 
    IP - ::1
   {"timestamp":"2022-07-28T19:00:37.108Z"}
error: uncaughtException: This error originated either by throwing inside of an async function without a catch block, or by rejecting a promise which was not handled with .catch(). The promise rejected with the reason "#<Object>".
UnhandledPromiseRejection: This error originated either by throwing inside of an async function without a catch block, or by rejecting a promise which was not handled with .catch(). The promise rejected with the reason "#<Object>". {"date":"Fri Jul 29 2022 18:01:51 GMT+0530 (India Standard Time)","error":{"code":"ERR_UNHANDLED_REJECTION"},"exception":true,"os":{"loadavg":[0,0,0],"uptime":1201558},"process":{"argv":["node","H:\\NodeJS\\fundooNotes\\fundooNotes\\src\\index.js"],"cwd":"H:\\NodeJS\\fundooNotes\\fundooNotes","execPath":"C:\\Program Files\\nodejs\\node.exe","gid":null,"memoryUsage":{"arrayBuffers":18286953,"external":19936700,"heapTotal":48238592,"heapUsed":43401696,"rss":80117760},"pid":13564,"uid":null,"version":"v16.14.2"},"stack":"UnhandledPromiseRejection: This error originated either by throwing inside of an async function without a catch block, or by rejecting a promise which was not handled with .catch(). The promise rejected with the reason \"#<Object>\".","timestamp":"2022-07-29T12:31:51.429Z","trace":[]}
error: uncaughtException: This error originated either by throwing inside of an async function without a catch block, or by rejecting a promise which was not handled with .catch(). The promise rejected with the reason "#<Object>".
UnhandledPromiseRejection: This error originated either by throwing inside of an async function without a catch block, or by rejecting a promise which was not handled with .catch(). The promise rejected with the reason "#<Object>". {"date":"Fri Jul 29 2022 18:03:24 GMT+0530 (India Standard Time)","error":{"code":"ERR_UNHANDLED_REJECTION"},"exception":true,"os":{"loadavg":[0,0,0],"uptime":1201651},"process":{"argv":["node","H:\\NodeJS\\fundooNotes\\fundooNotes\\src\\index.js"],"cwd":"H:\\NodeJS\\fundooNotes\\fundooNotes","execPath":"C:\\Program Files\\nodejs\\node.exe","gid":null,"memoryUsage":{"arrayBuffers":18374324,"external":19927922,"heapTotal":48762880,"heapUsed":43676824,"rss":81293312},"pid":14312,"uid":null,"version":"v16.14.2"},"stack":"UnhandledPromiseRejection: This error originated either by throwing inside of an async function without a catch block, or by rejecting a promise which was not handled with .catch(). The promise rejected with the reason \"#<Object>\".","timestamp":"2022-07-29T12:33:24.956Z","trace":[]}
error: uncaughtException: This error originated either by throwing inside of an async function without a catch block, or by rejecting a promise which was not handled with .catch(). The promise rejected with the reason "#<Object>".
UnhandledPromiseRejection: This error originated either by throwing inside of an async function without a catch block, or by rejecting a promise which was not handled with .catch(). The promise rejected with the reason "#<Object>". {"date":"Fri Jul 29 2022 18:04:42 GMT+0530 (India Standard Time)","error":{"code":"ERR_UNHANDLED_REJECTION"},"exception":true,"os":{"loadavg":[0,0,0],"uptime":1201729},"process":{"argv":["node","H:\\NodeJS\\fundooNotes\\fundooNotes\\src\\index.js"],"cwd":"H:\\NodeJS\\fundooNotes\\fundooNotes","execPath":"C:\\Program Files\\nodejs\\node.exe","gid":null,"memoryUsage":{"arrayBuffers":19354133,"external":22715108,"heapTotal":82386944,"heapUsed":54315392,"rss":115658752},"pid":16980,"uid":null,"version":"v16.14.2"},"stack":"UnhandledPromiseRejection: This error originated either by throwing inside of an async function without a catch block, or by rejecting a promise which was not handled with .catch(). The promise rejected with the reason \"#<Object>\".","timestamp":"2022-07-29T12:34:42.485Z","trace":[]}
error: uncaughtException: This error originated either by throwing inside of an async function without a catch block, or by rejecting a promise which was not handled with .catch(). The promise rejected with the reason "#<Object>".
UnhandledPromiseRejection: This error originated either by throwing inside of an async function without a catch block, or by rejecting a promise which was not handled with .catch(). The promise rejected with the reason "#<Object>". {"date":"Fri Jul 29 2022 18:16:12 GMT+0530 (India Standard Time)","error":{"code":"ERR_UNHANDLED_REJECTION"},"exception":true,"os":{"loadavg":[0,0,0],"uptime":1202419},"process":{"argv":["node","H:\\NodeJS\\fundooNotes\\fundooNotes\\src\\index.js"],"cwd":"H:\\NodeJS\\fundooNotes\\fundooNotes","execPath":"C:\\Program Files\\nodejs\\node.exe","gid":null,"memoryUsage":{"arrayBuffers":18293195,"external":19938449,"heapTotal":47976448,"heapUsed":44142280,"rss":80699392},"pid":13564,"uid":null,"version":"v16.14.2"},"stack":"UnhandledPromiseRejection: This error originated either by throwing inside of an async function without a catch block, or by rejecting a promise which was not handled with .catch(). The promise rejected with the reason \"#<Object>\".","timestamp":"2022-07-29T12:46:12.789Z","trace":[]}
error: 
    status - 500 
    message - ReferenceError: HttpStatus is not defined
    at noteValidator (H:\NodeJS\fundooNotes\fundooNotes\src\validators\/note.validator.js:11:16)
    at Layer.handle [as handle_request] (H:\NodeJS\fundooNotes\fundooNotes\node_modules\express\lib\router\layer.js:95:5)
    at next (H:\NodeJS\fundooNotes\fundooNotes\node_modules\express\lib\router\route.js:144:13)
    at _callee$ (H:\NodeJS\fundooNotes\fundooNotes\src\middlewares\/auth.middleware.js:25:5)
    at tryCatch (H:\NodeJS\fundooNotes\fundooNotes\node_modules\@babel\runtime\helpers\regeneratorRuntime.js:86:17)
    at Generator._invoke (H:\NodeJS\fundooNotes\fundooNotes\node_modules\@babel\runtime\helpers\regeneratorRuntime.js:66:24)
    at Generator.next (H:\NodeJS\fundooNotes\fundooNotes\node_modules\@babel\runtime\helpers\regeneratorRuntime.js:117:21)
    at asyncGeneratorStep (H:\NodeJS\fundooNotes\fundooNotes\node_modules\@babel\runtime\helpers\asyncToGenerator.js:3:24)
    at _next (H:\NodeJS\fundooNotes\fundooNotes\node_modules\@babel\runtime\helpers\asyncToGenerator.js:25:9)
    at processTicksAndRejections (node:internal/process/task_queues:96:5) 
    url - /api/v1/note/addNote 
    method - POST 
    IP - ::1
   {"timestamp":"2022-07-29T12:50:51.955Z"}
error: 
    status - 500 
    message - Error: User not exist
    at _callee2$ (H:\NodeJS\fundooNotes\fundooNotes\src\services\/user.service.js:23:11)
    at tryCatch (H:\NodeJS\fundooNotes\fundooNotes\node_modules\@babel\runtime\helpers\regeneratorRuntime.js:86:17)
    at Generator._invoke (H:\NodeJS\fundooNotes\fundooNotes\node_modules\@babel\runtime\helpers\regeneratorRuntime.js:66:24)
    at Generator.next (H:\NodeJS\fundooNotes\fundooNotes\node_modules\@babel\runtime\helpers\regeneratorRuntime.js:117:21)
    at asyncGeneratorStep (H:\NodeJS\fundooNotes\fundooNotes\node_modules\@babel\runtime\helpers\asyncToGenerator.js:3:24)
    at _next (H:\NodeJS\fundooNotes\fundooNotes\node_modules\@babel\runtime\helpers\asyncToGenerator.js:25:9)
    at processTicksAndRejections (node:internal/process/task_queues:96:5) 
    url - /api/v1/users/login 
    method - POST 
    IP - ::1
   {"timestamp":"2022-07-29T12:56:03.689Z"}
error: 
    status - 500 
    message - Error: User not exist
    at _callee2$ (H:\NodeJS\fundooNotes\fundooNotes\src\services\/user.service.js:23:11)
    at tryCatch (H:\NodeJS\fundooNotes\fundooNotes\node_modules\@babel\runtime\helpers\regeneratorRuntime.js:86:17)
    at Generator._invoke (H:\NodeJS\fundooNotes\fundooNotes\node_modules\@babel\runtime\helpers\regeneratorRuntime.js:66:24)
    at Generator.next (H:\NodeJS\fundooNotes\fundooNotes\node_modules\@babel\runtime\helpers\regeneratorRuntime.js:117:21)
    at asyncGeneratorStep (H:\NodeJS\fundooNotes\fundooNotes\node_modules\@babel\runtime\helpers\asyncToGenerator.js:3:24)
    at _next (H:\NodeJS\fundooNotes\fundooNotes\node_modules\@babel\runtime\helpers\asyncToGenerator.js:25:9)
    at processTicksAndRejections (node:internal/process/task_queues:96:5) 
    url - /api/v1/users/login 
    method - POST 
    IP - ::1
   {"timestamp":"2022-07-29T12:58:25.465Z"}
error: 
    status - 500 
    message - Error: User not exist
    at _callee2$ (H:\NodeJS\fundooNotes\fundooNotes\src\services\/user.service.js:23:11)
    at tryCatch (H:\NodeJS\fundooNotes\fundooNotes\node_modules\@babel\runtime\helpers\regeneratorRuntime.js:86:17)
    at Generator._invoke (H:\NodeJS\fundooNotes\fundooNotes\node_modules\@babel\runtime\helpers\regeneratorRuntime.js:66:24)
    at Generator.next (H:\NodeJS\fundooNotes\fundooNotes\node_modules\@babel\runtime\helpers\regeneratorRuntime.js:117:21)
    at asyncGeneratorStep (H:\NodeJS\fundooNotes\fundooNotes\node_modules\@babel\runtime\helpers\asyncToGenerator.js:3:24)
    at _next (H:\NodeJS\fundooNotes\fundooNotes\node_modules\@babel\runtime\helpers\asyncToGenerator.js:25:9)
    at processTicksAndRejections (node:internal/process/task_queues:96:5) 
    url - /api/v1/users/login 
    method - POST 
    IP - ::1
   {"timestamp":"2022-07-29T12:59:08.316Z"}
error: 
    status - 500 
    message - Error: User not exist
    at _callee2$ (H:\NodeJS\fundooNotes\fundooNotes\src\services\/user.service.js:23:11)
    at tryCatch (H:\NodeJS\fundooNotes\fundooNotes\node_modules\@babel\runtime\helpers\regeneratorRuntime.js:86:17)
    at Generator._invoke (H:\NodeJS\fundooNotes\fundooNotes\node_modules\@babel\runtime\helpers\regeneratorRuntime.js:66:24)
    at Generator.next (H:\NodeJS\fundooNotes\fundooNotes\node_modules\@babel\runtime\helpers\regeneratorRuntime.js:117:21)
    at asyncGeneratorStep (H:\NodeJS\fundooNotes\fundooNotes\node_modules\@babel\runtime\helpers\asyncToGenerator.js:3:24)
    at _next (H:\NodeJS\fundooNotes\fundooNotes\node_modules\@babel\runtime\helpers\asyncToGenerator.js:25:9)
    at processTicksAndRejections (node:internal/process/task_queues:96:5) 
    url - /api/v1/users/login 
    method - POST 
    IP - ::1
   {"timestamp":"2022-07-29T12:59:47.074Z"}
error: 
    status - 500 
    message - Error: User not exist
    at _callee2$ (H:\NodeJS\fundooNotes\fundooNotes\src\services\/user.service.js:23:11)
    at tryCatch (H:\NodeJS\fundooNotes\fundooNotes\node_modules\@babel\runtime\helpers\regeneratorRuntime.js:86:17)
    at Generator._invoke (H:\NodeJS\fundooNotes\fundooNotes\node_modules\@babel\runtime\helpers\regeneratorRuntime.js:66:24)
    at Generator.next (H:\NodeJS\fundooNotes\fundooNotes\node_modules\@babel\runtime\helpers\regeneratorRuntime.js:117:21)
    at asyncGeneratorStep (H:\NodeJS\fundooNotes\fundooNotes\node_modules\@babel\runtime\helpers\asyncToGenerator.js:3:24)
    at _next (H:\NodeJS\fundooNotes\fundooNotes\node_modules\@babel\runtime\helpers\asyncToGenerator.js:25:9)
    at processTicksAndRejections (node:internal/process/task_queues:96:5) 
    url - /api/v1/users/login 
    method - POST 
    IP - ::1
   {"timestamp":"2022-07-29T13:00:40.652Z"}
error: 
    status - 500 
    message - Error: User not exist
    at _callee2$ (H:\NodeJS\fundooNotes\fundooNotes\src\services\/user.service.js:23:11)
    at tryCatch (H:\NodeJS\fundooNotes\fundooNotes\node_modules\@babel\runtime\helpers\regeneratorRuntime.js:86:17)
    at Generator._invoke (H:\NodeJS\fundooNotes\fundooNotes\node_modules\@babel\runtime\helpers\regeneratorRuntime.js:66:24)
    at Generator.next (H:\NodeJS\fundooNotes\fundooNotes\node_modules\@babel\runtime\helpers\regeneratorRuntime.js:117:21)
    at asyncGeneratorStep (H:\NodeJS\fundooNotes\fundooNotes\node_modules\@babel\runtime\helpers\asyncToGenerator.js:3:24)
    at _next (H:\NodeJS\fundooNotes\fundooNotes\node_modules\@babel\runtime\helpers\asyncToGenerator.js:25:9)
    at processTicksAndRejections (node:internal/process/task_queues:96:5) 
    url - /api/v1/users/login 
    method - POST 
    IP - ::1
   {"timestamp":"2022-07-29T13:02:53.582Z"}
error: 
    status - 500 
    message - Error: User not exist
    at _callee2$ (H:\NodeJS\fundooNotes\fundooNotes\src\services\/user.service.js:23:11)
    at tryCatch (H:\NodeJS\fundooNotes\fundooNotes\node_modules\@babel\runtime\helpers\regeneratorRuntime.js:86:17)
    at Generator._invoke (H:\NodeJS\fundooNotes\fundooNotes\node_modules\@babel\runtime\helpers\regeneratorRuntime.js:66:24)
    at Generator.next (H:\NodeJS\fundooNotes\fundooNotes\node_modules\@babel\runtime\helpers\regeneratorRuntime.js:117:21)
    at asyncGeneratorStep (H:\NodeJS\fundooNotes\fundooNotes\node_modules\@babel\runtime\helpers\asyncToGenerator.js:3:24)
    at _next (H:\NodeJS\fundooNotes\fundooNotes\node_modules\@babel\runtime\helpers\asyncToGenerator.js:25:9)
    at processTicksAndRejections (node:internal/process/task_queues:96:5) 
    url - /api/v1/users/login 
    method - POST 
    IP - ::1
   {"timestamp":"2022-07-29T13:04:56.556Z"}
error: 
    status - 500 
    message - Error: User not exist
    at _callee2$ (H:\NodeJS\fundooNotes\fundooNotes\src\services\/user.service.js:22:11)
    at tryCatch (H:\NodeJS\fundooNotes\fundooNotes\node_modules\@babel\runtime\helpers\regeneratorRuntime.js:86:17)
    at Generator._invoke (H:\NodeJS\fundooNotes\fundooNotes\node_modules\@babel\runtime\helpers\regeneratorRuntime.js:66:24)
    at Generator.next (H:\NodeJS\fundooNotes\fundooNotes\node_modules\@babel\runtime\helpers\regeneratorRuntime.js:117:21)
    at asyncGeneratorStep (H:\NodeJS\fundooNotes\fundooNotes\node_modules\@babel\runtime\helpers\asyncToGenerator.js:3:24)
    at _next (H:\NodeJS\fundooNotes\fundooNotes\node_modules\@babel\runtime\helpers\asyncToGenerator.js:25:9)
    at processTicksAndRejections (node:internal/process/task_queues:96:5) 
    url - /api/v1/users/login 
    method - POST 
    IP - ::1
   {"timestamp":"2022-07-29T13:31:10.662Z"}
error: 
    status - 500 
    message - Error: User not exist
    at _callee2$ (H:\NodeJS\fundooNotes\fundooNotes\src\services\/user.service.js:22:11)
    at tryCatch (H:\NodeJS\fundooNotes\fundooNotes\node_modules\@babel\runtime\helpers\regeneratorRuntime.js:86:17)
    at Generator._invoke (H:\NodeJS\fundooNotes\fundooNotes\node_modules\@babel\runtime\helpers\regeneratorRuntime.js:66:24)
    at Generator.next (H:\NodeJS\fundooNotes\fundooNotes\node_modules\@babel\runtime\helpers\regeneratorRuntime.js:117:21)
    at asyncGeneratorStep (H:\NodeJS\fundooNotes\fundooNotes\node_modules\@babel\runtime\helpers\asyncToGenerator.js:3:24)
    at _next (H:\NodeJS\fundooNotes\fundooNotes\node_modules\@babel\runtime\helpers\asyncToGenerator.js:25:9)
    at processTicksAndRejections (node:internal/process/task_queues:96:5) 
    url - /api/v1/users/login 
    method - POST 
    IP - ::1
   {"timestamp":"2022-07-29T13:39:35.620Z"}
error: 
    status - 500 
    message - Error: User not exist
    at _callee2$ (H:\NodeJS\fundooNotes\fundooNotes\src\services\/user.service.js:22:11)
    at tryCatch (H:\NodeJS\fundooNotes\fundooNotes\node_modules\@babel\runtime\helpers\regeneratorRuntime.js:86:17)
    at Generator._invoke (H:\NodeJS\fundooNotes\fundooNotes\node_modules\@babel\runtime\helpers\regeneratorRuntime.js:66:24)
    at Generator.next (H:\NodeJS\fundooNotes\fundooNotes\node_modules\@babel\runtime\helpers\regeneratorRuntime.js:117:21)
    at asyncGeneratorStep (H:\NodeJS\fundooNotes\fundooNotes\node_modules\@babel\runtime\helpers\asyncToGenerator.js:3:24)
    at _next (H:\NodeJS\fundooNotes\fundooNotes\node_modules\@babel\runtime\helpers\asyncToGenerator.js:25:9)
    at processTicksAndRejections (node:internal/process/task_queues:96:5) 
    url - /api/v1/users/login 
    method - POST 
    IP - ::1
   {"timestamp":"2022-07-29T13:40:00.507Z"}
error: 
    status - 500 
    message - Error: User not exist
    at _callee2$ (H:\NodeJS\fundooNotes\fundooNotes\src\services\/user.service.js:22:11)
    at tryCatch (H:\NodeJS\fundooNotes\fundooNotes\node_modules\@babel\runtime\helpers\regeneratorRuntime.js:86:17)
    at Generator._invoke (H:\NodeJS\fundooNotes\fundooNotes\node_modules\@babel\runtime\helpers\regeneratorRuntime.js:66:24)
    at Generator.next (H:\NodeJS\fundooNotes\fundooNotes\node_modules\@babel\runtime\helpers\regeneratorRuntime.js:117:21)
    at asyncGeneratorStep (H:\NodeJS\fundooNotes\fundooNotes\node_modules\@babel\runtime\helpers\asyncToGenerator.js:3:24)
    at _next (H:\NodeJS\fundooNotes\fundooNotes\node_modules\@babel\runtime\helpers\asyncToGenerator.js:25:9)
    at processTicksAndRejections (node:internal/process/task_queues:96:5) 
    url - /api/v1/users/login 
    method - POST 
    IP - ::1
   {"timestamp":"2022-07-29T16:52:26.962Z"}
error: 
    status - 500 
    message - Error: User not exist
    at _callee2$ (H:\NodeJS\fundooNotes\fundooNotes\src\services\/user.service.js:22:11)
    at tryCatch (H:\NodeJS\fundooNotes\fundooNotes\node_modules\@babel\runtime\helpers\regeneratorRuntime.js:86:17)
    at Generator._invoke (H:\NodeJS\fundooNotes\fundooNotes\node_modules\@babel\runtime\helpers\regeneratorRuntime.js:66:24)
    at Generator.next (H:\NodeJS\fundooNotes\fundooNotes\node_modules\@babel\runtime\helpers\regeneratorRuntime.js:117:21)
    at asyncGeneratorStep (H:\NodeJS\fundooNotes\fundooNotes\node_modules\@babel\runtime\helpers\asyncToGenerator.js:3:24)
    at _next (H:\NodeJS\fundooNotes\fundooNotes\node_modules\@babel\runtime\helpers\asyncToGenerator.js:25:9)
    at processTicksAndRejections (node:internal/process/task_queues:96:5) 
    url - /api/v1/users/login 
    method - POST 
    IP - ::1
   {"timestamp":"2022-07-29T17:02:03.037Z"}
error: 
    status - 500 
    message - Error: User not exist
    at _callee2$ (H:\NodeJS\fundooNotes\fundooNotes\src\services\/user.service.js:22:11)
    at tryCatch (H:\NodeJS\fundooNotes\fundooNotes\node_modules\@babel\runtime\helpers\regeneratorRuntime.js:86:17)
    at Generator._invoke (H:\NodeJS\fundooNotes\fundooNotes\node_modules\@babel\runtime\helpers\regeneratorRuntime.js:66:24)
    at Generator.next (H:\NodeJS\fundooNotes\fundooNotes\node_modules\@babel\runtime\helpers\regeneratorRuntime.js:117:21)
    at asyncGeneratorStep (H:\NodeJS\fundooNotes\fundooNotes\node_modules\@babel\runtime\helpers\asyncToGenerator.js:3:24)
    at _next (H:\NodeJS\fundooNotes\fundooNotes\node_modules\@babel\runtime\helpers\asyncToGenerator.js:25:9)
    at processTicksAndRejections (node:internal/process/task_queues:96:5) 
    url - /api/v1/users/login 
    method - POST 
    IP - ::1
   {"timestamp":"2022-07-29T17:15:25.537Z"}
error: 
    status - 500 
    message - ValidationError: "Title" is required 
    url - /api/v1/note/addNote 
    method - POST 
    IP - ::1
   {"timestamp":"2022-07-29T17:26:17.568Z"}
error: uncaughtException: data is not defined
ReferenceError: data is not defined
    at _callee$ (H:\NodeJS\fundooNotes\fundooNotes\src\middlewares\/auth.middleware.js:29:13)
    at tryCatch (H:\NodeJS\fundooNotes\fundooNotes\node_modules\@babel\runtime\helpers\regeneratorRuntime.js:86:17)
    at Generator._invoke (H:\NodeJS\fundooNotes\fundooNotes\node_modules\@babel\runtime\helpers\regeneratorRuntime.js:66:24)
    at Generator.next (H:\NodeJS\fundooNotes\fundooNotes\node_modules\@babel\runtime\helpers\regeneratorRuntime.js:117:21)
    at asyncGeneratorStep (H:\NodeJS\fundooNotes\fundooNotes\node_modules\@babel\runtime\helpers\asyncToGenerator.js:3:24)
    at _next (H:\NodeJS\fundooNotes\fundooNotes\node_modules\@babel\runtime\helpers\asyncToGenerator.js:25:9)
    at processTicksAndRejections (node:internal/process/task_queues:96:5) {"date":"Fri Jul 29 2022 22:57:26 GMT+0530 (India Standard Time)","error":{},"exception":true,"os":{"loadavg":[0,0,0],"uptime":1219293},"process":{"argv":["node","H:\\NodeJS\\fundooNotes\\fundooNotes\\src\\index.js"],"cwd":"H:\\NodeJS\\fundooNotes\\fundooNotes","execPath":"C:\\Program Files\\nodejs\\node.exe","gid":null,"memoryUsage":{"arrayBuffers":18296402,"external":19850000,"heapTotal":48762880,"heapUsed":44233592,"rss":81080320},"pid":18248,"uid":null,"version":"v16.14.2"},"stack":"ReferenceError: data is not defined\n    at _callee$ (H:\\NodeJS\\fundooNotes\\fundooNotes\\src\\middlewares\\/auth.middleware.js:29:13)\n    at tryCatch (H:\\NodeJS\\fundooNotes\\fundooNotes\\node_modules\\@babel\\runtime\\helpers\\regeneratorRuntime.js:86:17)\n    at Generator._invoke (H:\\NodeJS\\fundooNotes\\fundooNotes\\node_modules\\@babel\\runtime\\helpers\\regeneratorRuntime.js:66:24)\n    at Generator.next (H:\\NodeJS\\fundooNotes\\fundooNotes\\node_modules\\@babel\\runtime\\helpers\\regeneratorRuntime.js:117:21)\n    at asyncGeneratorStep (H:\\NodeJS\\fundooNotes\\fundooNotes\\node_modules\\@babel\\runtime\\helpers\\asyncToGenerator.js:3:24)\n    at _next (H:\\NodeJS\\fundooNotes\\fundooNotes\\node_modules\\@babel\\runtime\\helpers\\asyncToGenerator.js:25:9)\n    at processTicksAndRejections (node:internal/process/task_queues:96:5)","timestamp":"2022-07-29T17:27:26.310Z","trace":[{"column":13,"file":"H:\\NodeJS\\fundooNotes\\fundooNotes\\src\\middlewares\\/auth.middleware.js","function":"_callee$","line":29,"method":null,"native":false},{"column":17,"file":"H:\\NodeJS\\fundooNotes\\fundooNotes\\node_modules\\@babel\\runtime\\helpers\\regeneratorRuntime.js","function":"tryCatch","line":86,"method":null,"native":false},{"column":24,"file":"H:\\NodeJS\\fundooNotes\\fundooNotes\\node_modules\\@babel\\runtime\\helpers\\regeneratorRuntime.js","function":"Generator._invoke","line":66,"method":"_invoke","native":false},{"column":21,"file":"H:\\NodeJS\\fundooNotes\\fundooNotes\\node_modules\\@babel\\runtime\\helpers\\regeneratorRuntime.js","function":"Generator.next","line":117,"method":"next","native":false},{"column":24,"file":"H:\\NodeJS\\fundooNotes\\fundooNotes\\node_modules\\@babel\\runtime\\helpers\\asyncToGenerator.js","function":"asyncGeneratorStep","line":3,"method":null,"native":false},{"column":9,"file":"H:\\NodeJS\\fundooNotes\\fundooNotes\\node_modules\\@babel\\runtime\\helpers\\asyncToGenerator.js","function":"_next","line":25,"method":null,"native":false},{"column":5,"file":"node:internal/process/task_queues","function":"processTicksAndRejections","line":96,"method":null,"native":false}]}
error: 
    status - 500 
    message - SyntaxError: Unexpected end of JSON input
    at JSON.parse (<anonymous>)
    at parse (H:\NodeJS\fundooNotes\fundooNotes\node_modules\body-parser\lib\types\json.js:89:19)
    at H:\NodeJS\fundooNotes\fundooNotes\node_modules\body-parser\lib\read.js:128:18
    at AsyncResource.runInAsyncScope (node:async_hooks:201:9)
    at invokeCallback (H:\NodeJS\fundooNotes\fundooNotes\node_modules\raw-body\index.js:231:16)
    at done (H:\NodeJS\fundooNotes\fundooNotes\node_modules\raw-body\index.js:220:7)
    at IncomingMessage.onEnd (H:\NodeJS\fundooNotes\fundooNotes\node_modules\raw-body\index.js:280:7)
    at IncomingMessage.emit (node:events:538:35)
    at IncomingMessage.emit (node:domain:475:12)
    at endReadableNT (node:internal/streams/readable:1345:12)
    at processTicksAndRejections (node:internal/process/task_queues:83:21) 
    url - /api/v1/note/addNote 
    method - POST 
    IP - ::1
   {"timestamp":"2022-07-29T17:35:46.779Z"}
error: uncaughtException: data is not defined
ReferenceError: data is not defined
    at _callee$ (H:\NodeJS\fundooNotes\fundooNotes\src\middlewares\/auth.middleware.js:29:12)
    at tryCatch (H:\NodeJS\fundooNotes\fundooNotes\node_modules\@babel\runtime\helpers\regeneratorRuntime.js:86:17)
    at Generator._invoke (H:\NodeJS\fundooNotes\fundooNotes\node_modules\@babel\runtime\helpers\regeneratorRuntime.js:66:24)
    at Generator.next (H:\NodeJS\fundooNotes\fundooNotes\node_modules\@babel\runtime\helpers\regeneratorRuntime.js:117:21)
    at asyncGeneratorStep (H:\NodeJS\fundooNotes\fundooNotes\node_modules\@babel\runtime\helpers\asyncToGenerator.js:3:24)
    at _next (H:\NodeJS\fundooNotes\fundooNotes\node_modules\@babel\runtime\helpers\asyncToGenerator.js:25:9)
    at processTicksAndRejections (node:internal/process/task_queues:96:5) {"date":"Fri Jul 29 2022 23:11:57 GMT+0530 (India Standard Time)","error":{},"exception":true,"os":{"loadavg":[0,0,0],"uptime":1220164},"process":{"argv":["node","H:\\NodeJS\\fundooNotes\\fundooNotes\\src\\index.js"],"cwd":"H:\\NodeJS\\fundooNotes\\fundooNotes","execPath":"C:\\Program Files\\nodejs\\node.exe","gid":null,"memoryUsage":{"arrayBuffers":18296405,"external":19850003,"heapTotal":49025024,"heapUsed":44239984,"rss":81162240},"pid":13084,"uid":null,"version":"v16.14.2"},"stack":"ReferenceError: data is not defined\n    at _callee$ (H:\\NodeJS\\fundooNotes\\fundooNotes\\src\\middlewares\\/auth.middleware.js:29:12)\n    at tryCatch (H:\\NodeJS\\fundooNotes\\fundooNotes\\node_modules\\@babel\\runtime\\helpers\\regeneratorRuntime.js:86:17)\n    at Generator._invoke (H:\\NodeJS\\fundooNotes\\fundooNotes\\node_modules\\@babel\\runtime\\helpers\\regeneratorRuntime.js:66:24)\n    at Generator.next (H:\\NodeJS\\fundooNotes\\fundooNotes\\node_modules\\@babel\\runtime\\helpers\\regeneratorRuntime.js:117:21)\n    at asyncGeneratorStep (H:\\NodeJS\\fundooNotes\\fundooNotes\\node_modules\\@babel\\runtime\\helpers\\asyncToGenerator.js:3:24)\n    at _next (H:\\NodeJS\\fundooNotes\\fundooNotes\\node_modules\\@babel\\runtime\\helpers\\asyncToGenerator.js:25:9)\n    at processTicksAndRejections (node:internal/process/task_queues:96:5)","timestamp":"2022-07-29T17:41:57.799Z","trace":[{"column":12,"file":"H:\\NodeJS\\fundooNotes\\fundooNotes\\src\\middlewares\\/auth.middleware.js","function":"_callee$","line":29,"method":null,"native":false},{"column":17,"file":"H:\\NodeJS\\fundooNotes\\fundooNotes\\node_modules\\@babel\\runtime\\helpers\\regeneratorRuntime.js","function":"tryCatch","line":86,"method":null,"native":false},{"column":24,"file":"H:\\NodeJS\\fundooNotes\\fundooNotes\\node_modules\\@babel\\runtime\\helpers\\regeneratorRuntime.js","function":"Generator._invoke","line":66,"method":"_invoke","native":false},{"column":21,"file":"H:\\NodeJS\\fundooNotes\\fundooNotes\\node_modules\\@babel\\runtime\\helpers\\regeneratorRuntime.js","function":"Generator.next","line":117,"method":"next","native":false},{"column":24,"file":"H:\\NodeJS\\fundooNotes\\fundooNotes\\node_modules\\@babel\\runtime\\helpers\\asyncToGenerator.js","function":"asyncGeneratorStep","line":3,"method":null,"native":false},{"column":9,"file":"H:\\NodeJS\\fundooNotes\\fundooNotes\\node_modules\\@babel\\runtime\\helpers\\asyncToGenerator.js","function":"_next","line":25,"method":null,"native":false},{"column":5,"file":"node:internal/process/task_queues","function":"processTicksAndRejections","line":96,"method":null,"native":false}]}
error: uncaughtException: This error originated either by throwing inside of an async function without a catch block, or by rejecting a promise which was not handled with .catch(). The promise rejected with the reason "#<Object>".
UnhandledPromiseRejection: This error originated either by throwing inside of an async function without a catch block, or by rejecting a promise which was not handled with .catch(). The promise rejected with the reason "#<Object>". {"date":"Fri Jul 29 2022 23:20:17 GMT+0530 (India Standard Time)","error":{"code":"ERR_UNHANDLED_REJECTION"},"exception":true,"os":{"loadavg":[0,0,0],"uptime":1220664},"process":{"argv":["node","H:\\NodeJS\\fundooNotes\\fundooNotes\\src\\index.js"],"cwd":"H:\\NodeJS\\fundooNotes\\fundooNotes","execPath":"C:\\Program Files\\nodejs\\node.exe","gid":null,"memoryUsage":{"arrayBuffers":18284366,"external":19837964,"heapTotal":49287168,"heapUsed":44081424,"rss":82022400},"pid":15612,"uid":null,"version":"v16.14.2"},"stack":"UnhandledPromiseRejection: This error originated either by throwing inside of an async function without a catch block, or by rejecting a promise which was not handled with .catch(). The promise rejected with the reason \"#<Object>\".","timestamp":"2022-07-29T17:50:18.007Z","trace":[]}
error: uncaughtException: data is not defined
ReferenceError: data is not defined
    at _callee$ (H:\NodeJS\fundooNotes\fundooNotes\src\middlewares\/auth.middleware.js:29:13)
    at tryCatch (H:\NodeJS\fundooNotes\fundooNotes\node_modules\@babel\runtime\helpers\regeneratorRuntime.js:86:17)
    at Generator._invoke (H:\NodeJS\fundooNotes\fundooNotes\node_modules\@babel\runtime\helpers\regeneratorRuntime.js:66:24)
    at Generator.next (H:\NodeJS\fundooNotes\fundooNotes\node_modules\@babel\runtime\helpers\regeneratorRuntime.js:117:21)
    at asyncGeneratorStep (H:\NodeJS\fundooNotes\fundooNotes\node_modules\@babel\runtime\helpers\asyncToGenerator.js:3:24)
    at _next (H:\NodeJS\fundooNotes\fundooNotes\node_modules\@babel\runtime\helpers\asyncToGenerator.js:25:9)
    at processTicksAndRejections (node:internal/process/task_queues:96:5) {"date":"Fri Jul 29 2022 23:26:26 GMT+0530 (India Standard Time)","error":{},"exception":true,"os":{"loadavg":[0,0,0],"uptime":1221033},"process":{"argv":["node","H:\\NodeJS\\fundooNotes\\fundooNotes\\src\\index.js"],"cwd":"H:\\NodeJS\\fundooNotes\\fundooNotes","execPath":"C:\\Program Files\\nodejs\\node.exe","gid":null,"memoryUsage":{"arrayBuffers":18286946,"external":19957369,"heapTotal":49025024,"heapUsed":44596016,"rss":80556032},"pid":13792,"uid":null,"version":"v16.14.2"},"stack":"ReferenceError: data is not defined\n    at _callee$ (H:\\NodeJS\\fundooNotes\\fundooNotes\\src\\middlewares\\/auth.middleware.js:29:13)\n    at tryCatch (H:\\NodeJS\\fundooNotes\\fundooNotes\\node_modules\\@babel\\runtime\\helpers\\regeneratorRuntime.js:86:17)\n    at Generator._invoke (H:\\NodeJS\\fundooNotes\\fundooNotes\\node_modules\\@babel\\runtime\\helpers\\regeneratorRuntime.js:66:24)\n    at Generator.next (H:\\NodeJS\\fundooNotes\\fundooNotes\\node_modules\\@babel\\runtime\\helpers\\regeneratorRuntime.js:117:21)\n    at asyncGeneratorStep (H:\\NodeJS\\fundooNotes\\fundooNotes\\node_modules\\@babel\\runtime\\helpers\\asyncToGenerator.js:3:24)\n    at _next (H:\\NodeJS\\fundooNotes\\fundooNotes\\node_modules\\@babel\\runtime\\helpers\\asyncToGenerator.js:25:9)\n    at processTicksAndRejections (node:internal/process/task_queues:96:5)","timestamp":"2022-07-29T17:56:26.459Z","trace":[{"column":13,"file":"H:\\NodeJS\\fundooNotes\\fundooNotes\\src\\middlewares\\/auth.middleware.js","function":"_callee$","line":29,"method":null,"native":false},{"column":17,"file":"H:\\NodeJS\\fundooNotes\\fundooNotes\\node_modules\\@babel\\runtime\\helpers\\regeneratorRuntime.js","function":"tryCatch","line":86,"method":null,"native":false},{"column":24,"file":"H:\\NodeJS\\fundooNotes\\fundooNotes\\node_modules\\@babel\\runtime\\helpers\\regeneratorRuntime.js","function":"Generator._invoke","line":66,"method":"_invoke","native":false},{"column":21,"file":"H:\\NodeJS\\fundooNotes\\fundooNotes\\node_modules\\@babel\\runtime\\helpers\\regeneratorRuntime.js","function":"Generator.next","line":117,"method":"next","native":false},{"column":24,"file":"H:\\NodeJS\\fundooNotes\\fundooNotes\\node_modules\\@babel\\runtime\\helpers\\asyncToGenerator.js","function":"asyncGeneratorStep","line":3,"method":null,"native":false},{"column":9,"file":"H:\\NodeJS\\fundooNotes\\fundooNotes\\node_modules\\@babel\\runtime\\helpers\\asyncToGenerator.js","function":"_next","line":25,"method":null,"native":false},{"column":5,"file":"node:internal/process/task_queues","function":"processTicksAndRejections","line":96,"method":null,"native":false}]}
